Workbook

Sheet Data Source
B2: Date | C2: Financials | D2: Amount
B3: 1.1.2014 | C3: Revenue - Supermarkets | D3: 72
B4: 1.1.2014 | C4: Cogs - Supermarkets | D4: 47
B5: 1.1.2014 | C5: Revenue - Discounters | D5: 37
B6: 1.1.2014 | C6: Cogs - Discounters | D6: 20
B7: 1.1.2014 | C7: Revenue - Grocery | D7: 36
B8: 1.1.2014 | C8: Cogs - Grocery | D8: 17
B9: 1.1.2014 | C9: Revenue - Retail | D9: 57
B10: 1.1.2014 | C10: Cogs - Retail | D10: 32
B11: 1.1.2014 | C11: Operating expenses | D11: 95.4
B12: 1.1.2014 | C12: D&A | D12: 2
B13: 1.1.2014 | C13: Interest expenses | D13: 5
B14: 1.1.2014 | C14: Taxes | D14: 17.29
... B437: 12.1.2016 | C437: Other revenue | D437: 628

Sheet BS 2014
A1: $ in mln | C1: 42004
A2: Receivables - Discounters | C2: 44.609
A3: Receivables - Other | C3: 33.097
A4: Receivables - Grocery | C4: 31.658
A5: Receivables - Retail | C5: 20.146
A6: Receivables - Supermarkets | C6: 14.39
A7: Trade Receivables | C7: 143.9
A9: Inventory - Discounters | C9: 29.75
A10: Inventory - Supermarkets | C10: 18.7
A11: Inventory - Grocery | C11: 16.15
A12: Inventory - Retail | C12: 11.05
A13: Inventory - Other | C13: 9.35
... A55: Liabilities & Equity | C55: 932.1

Sheet BS 2015
A1: $ in mln | B1: Code I | C1: 42369
A2: Receivables - Discounters | B2: R | C2: 40.248
A3: Receivables - Grocery | B3: R | C3: 34.056
A4: Receivables - Other | B4: R | C4: 29.412
A5: Receivables - Retail | B5: R | C5: 27.864
A6: Receivables - Supermarkets | B6: R | C6: 23.22
A7: Trade Receivables | C7: 154.8
A9: Inventory - Discounters | B9: I | C9: 24.84
A10: Inventory - Supermarkets | B10: I | C10: 20.24
A11: Inventory - Grocery | B11: I | C11: 17.48
A12: Inventory - Other | B12: I | C12: 17.48
A13: Inventory - Retail | B13: I | C13: 11.96
A14: Inventory | B14: I | C14: 92
A16: PP&E - Machinery | B16: P | C16: 346.475
A17: PP&E - Other | B17: P | C17: 139.525
A18: PP&E - IT | B18: P | C18: 125.575
A19: PP&E - Vehicles | B19: P | C19: 20.925
A20: PP&E | B20: P | C20: 632.5
A22: Cash - Bank Accounts | B22: C | C22: 13.298
... A24: Cash - Cash at hand | B24: C | C24: 3.052
A25: Cash | C25: 21.8
A27: Other assets | B27: O | C27: 46.9
A28: Other assets | C28: 46.9
A30: Assets | C30: 948
A32: Trade Payables - Discounters | B32: T | C32: 19.981
A33: Trade Payables - Retail | B33: T | C33: 15.847
A34: Trade Payables - Other | B34: T | C34: 14.469
A35: Trade Payables - Grocery | B35: T | C35: 10.335
A36: Trade Payables - Supermarkets | B36: T | C36: 8.268
A37: Trade Payables | C37: 68.9
A39: Provisions - Taxes | B39: P | C39: 17.507
A40: Provisions - Legal | B40: P | C40: 6.601
A41: Provisions - Other | B41: P | C41: 4.592
A42: Provisions | C42: 28.7
A44: Financial Liabilities vs. Banks | B44: F | C44: 610.4
A45: Financial Liabilities | C45: 610.4
A47: Other liabilities | B47: O | C47: 43.3
A48: Other liabilities | C48: 43.3
A50: Retained Earnings | B50: E | C50: 161.525
A51: Minority interest | B51: E | C51: 18.425
...

Sheet BS 2016
A1: $ in mln | B1: Code I | C1: Code II | D1: 42735
A2: Receivables - Discounters | B2: R | C2: A | D2: 44.018
A3: Receivables - Grocery | B3: R | C3: A | D3: 40.632
A4: Receivables - Other | B4: R | C4: A | D4: 32.167
A5: Receivables - Retail | B5: R | C5: A | D5: 27.088
A6: Receivables - Supermarkets | B6: R | C6: A | D6: 25.395
A7: Trade Receivables | D7: 169.3
A9: Inventory - Discounters | B9: I | C9: A | D9: 26.4
A10: Inventory - Supermarkets | B10: I | C10: A | D10: 25.3
A11: Inventory - Grocery | B11: I | C11: A | D11: 20.9
A12: Inventory - Other | B12: I | C12: A | D12: 20.9
A13: Inventory - Retail | B13: I | C13: A | D13: 16.5
A14: Inventory | B14: I | D14: 110
A16: PP&E - Machinery | B16: P | C16: A | D16: 350.51
A17: PP&E - Other | B17: P | C17: A | D17: 146.71
A18: PP&E - IT | B18: P | C18: A | D18: 133.735
A19: PP&E - Vehicles | B19: P | C19: A | D19: 28.545
A20: PP&E | D20: 659.5
A22: Cash - Bank Accounts | B22: C | C22: A | D22: 125.4
A23: Cash - T-bills | B23: C | C23: A | D23: 59.4
A24: Cash - Cash at hand | B24: C | C24: A | D24: 35.2
A25: Cash | D25: 220
A27: Other assets | B27: O | C27: A | D27: 68
A28: Other assets | D28: 68
A30: Assets | D30: 1226.8
A32: Trade Payables - Discounters | B32: T | C32: L | D32: 19.981
A33: Trade Payables - Retail | B33: T | C33: L | D33: 15.847
A34: Trade Payables - Other | B34: T | C34: L | D34: 14.469
A35: Trade Payables - Grocery | B35: T | C35: L | D35: 10.335
A36: Trade Payables - Supermarkets | B36: T | C36: L | D36: 8.268
A37: Trade Payables | D37: 68.9
A39: Provisions - Taxes | B39: P | C39: L | D39: 17.507
A40: Provisions - Legal | B40: P | C40: L | D40: 6.601
A41: Provisions - Other | B41: P | C41: L | D41: 4.592
A42: Provisions | D42: 28.7
A44: Financial Liabilities vs. Banks | B44: F | C44: L | D44: 605
A45: Financial Liabilities | D45: 605
A47: Other liabilities | B47: O | C47: L | D47: 38.9
A48: Other liabilities | D48: 38.9
A50: Retained Earnings | B50: E | C50: E | D50: 450.125
...

Sheet Work
A3: Date | B3: Year | C3: Financials | D3: Amount | E3: Mapping
A4: 41640 | B4: =YEAR(A4) -> 2014 | C4: Revenue - Supermarkets | D4: 72 | E4: Revenue
A5: 41640 | B5: =YEAR(A5) -> 2014 | C5: Cogs - Supermarkets | D5: 47 | E5: Cost of goods sold
A6: 41640 | B6: =YEAR(A6) -> 2014 | C6: Revenue - Discounters | D6: 37 | E6: Revenue
A7: 41640 | B7: =YEAR(A7) -> 2014 | C7: Cogs - Discounters | D7: 20 | E7: Cost of goods sold
A8: 41640 | B8: =YEAR(A8) -> 2014 | C8: Revenue - Grocery | D8: 36 | E8: Revenue
A9: 41640 | B9: =YEAR(A9) -> 2014 | C9: Cogs - Grocery | D9: 17 | E9: Cost of goods sold
A10: 41640 | B10: =YEAR(A10) -> 2014 | C10: Revenue - Retail | D10: 57 | E10: Revenue
A11: 41640 | B11: =YEAR(A11) -> 2014 | C11: Cogs - Retail | D11: 32 | E11: Cost of goods sold
A12: 41640 | B12: =YEAR(A12) -> 2014 | C12: Operating expenses | D12: 95.4 | E12: Operating expenses
A13: 41640 | B13: =YEAR(A13) -> 2014 | C13: D&A | D13: 2 | E13: D&A
A14: 41640 | B14: =YEAR(A14) -> 2014 | C14: Interest expenses | D14: 5 | E14: Interest expenses
A15: 41640 | B15: =YEAR(A15) -> 2014 | C15: Taxes | D15: 17.29 | E15: Taxes
... A438: 42381 | B438: =YEAR(A438) -> 2016 | C438: Other revenue | D438: 628 | E438: Revenue

Sheet P&L
A1: P&L
A2: Scenario: | B2: Best case | H2: Forecast
A3: $ in million | B3: 2014 | C3: 2015 | D3: 2016 | F3: Var % 14-15 | G3: Var % 15-16 | H3: 2017 | I3: 2018 | J3: 2019 | K3: 2020 | L3: 2021
A4: Revenue | B4: =+SUMIFS(Work!$D:$D,Work!$E:$E,'P&L'!$A4,Work!$B:$B,'P&L'!B$3) -> 2922 | C4: =+SUMIFS(Work!$D:$D,Work!$E:$E,'P&L'!$A4,Work!$B:$B,'P&L'!C$3) -> 2984 | D4: =+SUMIFS(Work!$D:$D,Work!$E:$E,'P&L'!$A4,Work!$B:$B,'P&L'!D$3) -> 3040 | F4: =C4/B4-1 -> 0.021218344 | G4: =D4/C4-1 -> 0.018766756 | H4: =D4*(1+H19) -> 3131.2 | I4: =H4*(1+I19) -> 3225.136 | J4: =I4*(1+J19) -> 3321.8901 | K4: =J4*(1+K19) -> 3421.5468 | L4: =K4*(1+L19) -> 3524.1932
A5: Cost of goods sold | B5: =-1*SUMIFS(Work!$D:$D,Work!$E:$E,'P&L'!$A5,Work!$B:$B,'P&L'!B$3) -> -1401 | C5: =-1*SUMIFS(Work!$D:$D,Work!$E:$E,'P&L'!$A5,Work!$B:$B,'P&L'!C$3) -> -1383 | D5: =-1*SUMIFS(Work!$D:$D,Work!$E:$E,'P&L'!$A5,Work!$B:$B,'P&L'!D$3) -> -1367 | F5: =C5/B5-1 -> -0.012847966 | G5: =D5/C5-1 -> -0.011569053 | H5: =H4*H25 -> -1409.04 | I5: =I4*I25 -> -1451.3112 | J5: =J4*J25 -> -1494.8505 | K5: =K4*K25 -> -1539.6961 | L5: =L4*L25 -> -1585.8869
A6: Gross Profit | B6: =SUM(B4,B5) -> 1521 | C6: =SUM(C4,C5) -> 1601 | D6: =SUM(D4,D5) -> 1673 | F6: =C6/B6-1 -> 0.052596976 | G6: =D6/C6-1 -> 0.044971893 | H6: =SUM(H4:H5) -> 1722.16 | I6: =SUM(I4:I5) -> 1773.8248 | J6: =SUM(J4:J5) -> 1827.0395 | K6: =SUM(K4:K5) -> 1881.8507 | L6: =SUM(L4:L5) -> 1938.3063
A7: Operating expenses | B7: =-1*SUMIFS(Work!$D:$D,Work!$E:$E,'P&L'!$A7,Work!$B:$B,'P&L'!B$3) -> -1212.18 | C7: =-1*SUMIFS(Work!$D:$D,Work!$E:$E,'P&L'!$A7,Work!$B:$B,'P&L'!C$3) -> -1245.34 | D7: =-1*SUMIFS(Work!$D:$D,Work!$E:$E,'P&L'!$A7,Work!$B:$B,'P&L'!D$3) -> -1068.24 | F7: =C7/B7-1 -> 0.027355673 | G7: =D7/C7-1 -> -0.14221016 | H7: =H4*H31 -> -1095.92 | I7: =I4*I31 -> -1128.7976 | J7: =J4*J31 -> -1162.6615 | K7: =K4*K31 -> -1197.5414 | L7: =L4*L31 -> -1233.4676
A8: EBITDA | B8: =SUM(B6,B7) -> 308.82 | C8: =SUM(C6,C7) -> 355.66 | D8: =SUM(D6,D7) -> 604.76 | F8: =C8/B8-1 -> 0.15167411 | G8: =D8/C8-1 -> 0.70038801 | H8: =SUM(H6:H7) -> 626.24 | I8: =SUM(I6:I7) -> 645.0272 | J8: =SUM(J6:J7) -> 664.37802 | K8: =SUM(K6:K7) -> 684.30936 | L8: =SUM(L6:L7) -> 704.83864
A9: D&A | B9: =-1*SUMIFS(Work!$D:$D,Work!$E:$E,'P&L'!$A9,Work!$B:$B,'P&L'!B$3) -> -31 | C9: =-1*SUMIFS(Work!$D:$D,Work!$E:$E,'P&L'!$A9,Work!$B:$B,'P&L'!C$3) -> -44 | D9: =-1*SUMIFS(Work!$D:$D,Work!$E:$E,'P&L'!$A9,Work!$B:$B,'P&L'!D$3) -> -41 | F9: =C9/B9-1 -> 0.41935484 | G9: =D9/C9-1 -> -0.068181818 | H9: ='FA Roll Forward'!F8 -> -44.314229 | I9: ='FA Roll Forward'!G8 -> -45.260067 | J9: ='FA Roll Forward'!H8 -> -46.226092 | K9: ='FA Roll Forward'!I8 -> -47.212736 | L9: ='FA Roll Forward'!J8 -> -48.220438
A10: EBIT | B10: =SUM(B8,B9) -> 277.82 | C10: =SUM(C8,C9) -> 311.66 | D10: =SUM(D8,D9) -> 563.76 | F10: =C10/B10-1 -> 0.12180549 | G10: =D10/C10-1 -> 0.80889431 | H10: =SUM(H8:H9) -> 581.92577 | I10: =SUM(I8:I9) -> 599.76713 | J10: =SUM(J8:J9) -> 618.15192 | K10: =SUM(K8:K9) -> 637.09662 | L10: =SUM(L8:L9) -> 656.6182
A11: Interest expenses | B11: =-1*SUMIFS(Work!$D:$D,Work!$E:$E,'P&L'!$A11,Work!$B:$B,'P&L'!B$3) -> -56 | C11: =-1*SUMIFS(Work!$D:$D,Work!$E:$E,'P&L'!$A11,Work!$B:$B,'P&L'!C$3) -> -65 | D11: =-1*SUMIFS(Work!$D:$D,Work!$E:$E,'P&L'!$A11,Work!$B:$B,'P&L'!D$3) -> -52 | F11: =C11/B11-1 -> 0.16071429 | G11: =D11/C11-1 -> -0.2 | H11: ='Financial Liabilities'!C18 -> -54.45 | I11: ='Financial Liabilities'!D18 -> -50.866096 | J11: ='Financial Liabilities'!E18 -> -46.959641 | K11: ='Financial Liabilities'!F18 -> -42.701605 | L11: ='Financial Liabilities'!G18 -> -38.060345
A12: EBT | B12: =SUM(B10,B11) -> 221.82 | C12: =SUM(C10,C11) -> 246.66 | D12: =SUM(D10,D11) -> 511.76 | F12: =C12/B12-1 -> 0.11198269 | G12: =D12/C12-1 -> 1.0747588 | H12: =SUM(H10:H11) -> 527.47577 | I12: =SUM(I10:I11) -> 548.90104 | J12: =SUM(J10:J11) -> 571.19228 | K12: =SUM(K10:K11) -> 594.39502 | L12: =SUM(L10:L11) -> 618.55785
A13: Taxes | B13: =-1*SUMIFS(Work!$D:$D,Work!$E:$E,'P&L'!$A13,Work!$B:$B,'P&L'!B$3) -> -207.52 | C13: =-1*SUMIFS(Work!$D:$D,Work!$E:$E,'P&L'!$A13,Work!$B:$B,'P&L'!C$3) -> -209.98 | D13: =-1*SUMIFS(Work!$D:$D,Work!$E:$E,'P&L'!$A13,Work!$B:$B,'P&L'!D$3) -> -208.58 | F13: =C13/B13-1 -> 0.011854279 | G13: =D13/C13-1 -> -0.0066673016 | H13: =H12*H37 -> -184.61652 | I13: =I12*I37 -> -192.11536 | J13: =J12*J37 -> -199.9173 | K13: =K12*K37 -> -208.03826 | L13: =L12*L37 -> -216.49525
A14: Net income | B14: =SUM(B12,B13) -> 14.3 | C14: =SUM(C12,C13) -> 36.68 | D14: =SUM(D12,D13) -> 303.18 | F14: =C14/B14-1 -> 1.565035 | G14: =D14/C14-1 -> 7.2655398 | H14: =SUM(H12:H13) -> 342.85925 | I14: =SUM(I12:I13) -> 356.78567 | J14: =SUM(J12:J13) -> 371.27498 | K14: =SUM(K12:K13) -> 386.35676 | L14: =SUM(L12:L13) -> 402.0626
A16: Scenarios:
A18: Revenue % growth
A19: Selected Case | H19: =OFFSET(H19,MATCH($B$2,$A20:$A22,0),0) -> 0.03 | I19: =OFFSET(I19,MATCH($B$2,$A20:$A22,0),0) -> 0.03 | J19: =OFFSET(J19,MATCH($B$2,$A20:$A22,0),0) -> 0.03 | K19: =OFFSET(K19,MATCH($B$2,$A20:$A22,0),0) -> 0.03 | L19: =OFFSET(L19,MATCH($B$2,$A20:$A22,0),0) -> 0.03
A20: Best case | H20: 0.03 | I20: 0.03 | J20: 0.03 | K20: 0.03 | L20: 0.03
A21: Base case | H21: 0.02 | I21: 0.02 | J21: 0.02 | K21: 0.02 | L21: 0.02
A22: Worst case | H22: 0.01 | I22: 0.01 | J22: 0.01 | K22: 0.01 | L22: 0.01
A24: Cogs as % of Revenues
A25: Selected Case | H25: =OFFSET(H25,MATCH($B$2,$A26:$A28,0),0) -> -0.45 | I25: =OFFSET(I25,MATCH($B$2,$A26:$A28,0),0) -> -0.45 | J25: =OFFSET(J25,MATCH($B$2,$A26:$A28,0),0) -> -0.45 | K25: =OFFSET(K25,MATCH($B$2,$A26:$A28,0),0) -> -0.45 | L25: =OFFSET(L25,MATCH($B$2,$A26:$A28,0),0) -> -0.45
A26: Best case | B26: =B$5/B$4 -> -0.47946612 | C26: =C$5/C$4 -> -0.46347185 | D26: =D$5/D$4 -> -0.44967105 | H26: -0.45 | I26: -0.45 | J26: -0.45 | K26: -0.45 | L26: -0.45
A27: Base case | B27: =B$5/B$4 -> -0.47946612 | C27: =C$5/C$4 -> -0.46347185 | D27: =D$5/D$4 -> -0.44967105 | H27: -0.46 | I27: -0.46 | J27: -0.46 | K27: -0.46 | L27: -0.46
A28: Worst case | B28: =B$5/B$4 -> -0.47946612 | C28: =C$5/C$4 -> -0.46347185 | D28: =D$5/D$4 -> -0.44967105 | H28: -0.47 | I28: -0.47 | J28: -0.47 | K28: -0.47 | L28: -0.47
A30: Opex as % of Revenues
A31: Selected Case | H31: =OFFSET(H31,MATCH($B$2,$A32:$A34,0),0) -> -0.35 | I31: =OFFSET(I31,MATCH($B$2,$A32:$A34,0),0) -> -0.35 | J31: =OFFSET(J31,MATCH($B$2,$A32:$A34,0),0) -> -0.35 | K31: =OFFSET(K31,MATCH($B$2,$A32:$A34,0),0) -> -0.35 | L31: =OFFSET(L31,MATCH($B$2,$A32:$A34,0),0) -> -0.35
A32: Best case | B32: =B$7/B$4 -> -0.414846 | C32: =C$7/C$4 -> -0.41733914 | D32: =D$7/D$4 -> -0.35139474 | H32: -0.35 | I32: -0.35 | J32: -0.35 | K32: -0.35 | L32: -0.35
A33: Base case | B33: =B$7/B$4 -> -0.414846 | C33: =C$7/C$4 -> -0.41733914 | D33: =D$7/D$4 -> -0.35139474 | H33: -0.39 | I33: -0.39 | J33: -0.39 | K33: -0.39 | L33: -0.39
A34: Worst case | B34: =B$7/B$4 -> -0.414846 | C34: =C$7/C$4 -> -0.41733914 | D34: =D$7/D$4 -> -0.35139474 | H34: -0.41 | I34: -0.41 | J34: -0.41 | K34: -0.41 | L34: -0.41
A37: Taxes % | H37: -0.35 | I37: -0.35 | J37: -0.35 | K37: -0.35 | L37: -0.35

Sheet BS
B2: Balance Sheet
F4: Forecast
B6: $ in million | C6: 42004 | D6: 42369 | E6: 42735 | F6: 43100 | G6: 43465 | H6: 43830 | I6: 44196 | J6: 44561
B7: Trade Receivables | C7: =INDEX('BS 2014'!$1:$1048576,MATCH(BS!$B7,'BS 2014'!$A:$A,0),MATCH(C$6,'BS 2014'!$1:$1,0)) -> 143.9 | D7: =INDEX('BS 2015'!$1:$1048576,MATCH(BS!$B7,'BS 2015'!$A:$A,0),MATCH(D$6,'BS 2015'!$1:$1,0)) -> 154.8 | E7: =INDEX('BS 2016'!$1:$1048576,MATCH(BS!$B7,'BS 2016'!$A:$A,0),MATCH(E$6,'BS 2016'!$1:$1,0)) -> 169.3 | F7: =(F21*'P&L'!H4)/360 -> 163.67258 | G7: =(G21*'P&L'!I4)/360 -> 168.58276 | H7: =(H21*'P&L'!J4)/360 -> 173.64024 | I7: =(I21*'P&L'!K4)/360 -> 178.84945 | J7: =(J21*'P&L'!L4)/360 -> 184.21493
B8: Inventory | C8: =INDEX('BS 2014'!$1:$1048576,MATCH(BS!$B8,'BS 2014'!$A:$A,0),MATCH(C$6,'BS 2014'!$1:$1,0)) -> 85 | D8: =INDEX('BS 2015'!$1:$1048576,MATCH(BS!$B8,'BS 2015'!$A:$A,0),MATCH(D$6,'BS 2015'!$1:$1,0)) -> 92 | E8: =INDEX('BS 2016'!$1:$1048576,MATCH(BS!$B8,'BS 2016'!$A:$A,0),MATCH(E$6,'BS 2016'!$1:$1,0)) -> 110 | F8: =-F23*'P&L'!H$5/360 -> 97.534304 | G8: =-G23*'P&L'!I$5/360 -> 100.46033 | H8: =-H23*'P&L'!J$5/360 -> 103.47414 | I8: =-I23*'P&L'!K$5/360 -> 106.57837 | J8: =-J23*'P&L'!L$5/360 -> 109.77572
B9: PP&E | C9: =INDEX('BS 2014'!$1:$1048576,MATCH(BS!$B9,'BS 2014'!$A:$A,0),MATCH(C$6,'BS 2014'!$1:$1,0)) -> 632.5 | D9: =INDEX('BS 2015'!$1:$1048576,MATCH(BS!$B9,'BS 2015'!$A:$A,0),MATCH(D$6,'BS 2015'!$1:$1,0)) -> 632.5 | E9: =INDEX('BS 2016'!$1:$1048576,MATCH(BS!$B9,'BS 2016'!$A:$A,0),MATCH(E$6,'BS 2016'!$1:$1,0)) -> 659.5 | F9: ='FA Roll Forward'!F10 -> 673.57628 | G9: ='FA Roll Forward'!G10 -> 687.95301 | H9: ='FA Roll Forward'!H10 -> 702.63659 | I9: ='FA Roll Forward'!I10 -> 717.63358 | J9: ='FA Roll Forward'!J10 -> 732.95066
B10: Cash | C10: =INDEX('BS 2014'!$1:$1048576,MATCH(BS!$B10,'BS 2014'!$A:$A,0),MATCH(C$6,'BS 2014'!$1:$1,0)) -> 24.8 | D10: =INDEX('BS 2015'!$1:$1048576,MATCH(BS!$B10,'BS 2015'!$A:$A,0),MATCH(D$6,'BS 2015'!$1:$1,0)) -> 21.8 | E10: =INDEX('BS 2016'!$1:$1048576,MATCH(BS!$B10,'BS 2016'!$A:$A,0),MATCH(E$6,'BS 2016'!$1:$1,0)) -> 220 | F10: =E10+'Cash flow'!C19 -> 409.58712 | G10: =F10+'Cash flow'!D19 -> 559.82481 | H10: =G10+'Cash flow'!E19 -> 714.36122 | I10: =H10+'Cash flow'!F19 -> 873.18825 | J10: =I10+'Cash flow'!G19 -> 1036.2848
B11: Other assets | C11: =INDEX('BS 2014'!$1:$1048576,MATCH(BS!$B11,'BS 2014'!$A:$A,0),MATCH(C$6,'BS 2014'!$1:$1,0)) -> 45.9 | D11: =INDEX('BS 2015'!$1:$1048576,MATCH(BS!$B11,'BS 2015'!$A:$A,0),MATCH(D$6,'BS 2015'!$1:$1,0)) -> 46.9 | E11: =INDEX('BS 2016'!$1:$1048576,MATCH(BS!$B11,'BS 2016'!$A:$A,0),MATCH(E$6,'BS 2016'!$1:$1,0)) -> 68 | F11: =F24*'P&L'!H$4 -> 56.146589 | G11: =G24*'P&L'!I$4 -> 57.830987 | H11: =H24*'P&L'!J$4 -> 59.565916 | I11: =I24*'P&L'!K$4 -> 61.352894 | J11: =J24*'P&L'!L$4 -> 63.193481
B12: Assets | C12: =SUM(C7:C11) -> 932.1 | D12: =SUM(D7:D11) -> 948 | E12: =SUM(E7:E11) -> 1226.8 | F12: =SUM(F7:F11) -> 1400.5169 | G12: =SUM(G7:G11) -> 1574.6519 | H12: =SUM(H7:H11) -> 1753.6781 | I12: =SUM(I7:I11) -> 1937.6025 | J12: =SUM(J7:J11) -> 2126.4196
B14: Trade Payables | C14: =INDEX('BS 2014'!$1:$1048576,MATCH(BS!$B14,'BS 2014'!$A:$A,0),MATCH(C$6,'BS 2014'!$1:$1,0)) -> 68 | D14: =INDEX('BS 2015'!$1:$1048576,MATCH(BS!$B14,'BS 2015'!$A:$A,0),MATCH(D$6,'BS 2015'!$1:$1,0)) -> 68.9 | E14: =INDEX('BS 2016'!$1:$1048576,MATCH(BS!$B14,'BS 2016'!$A:$A,0),MATCH(E$6,'BS 2016'!$1:$1,0)) -> 68.9 | F14: =-F22*'P&L'!H$5/360 -> 69.868814 | G14: =-G22*'P&L'!I$5/360 -> 71.964879 | H14: =-H22*'P&L'!J$5/360 -> 74.123825 | I14: =-I22*'P&L'!K$5/360 -> 76.34754 | J14: =-J22*'P&L'!L$5/360 -> 78.637966
B15: Provisions | C15: =INDEX('BS 2014'!$1:$1048576,MATCH(BS!$B15,'BS 2014'!$A:$A,0),MATCH(C$6,'BS 2014'!$1:$1,0)) -> 32.5 | D15: =INDEX('BS 2015'!$1:$1048576,MATCH(BS!$B15,'BS 2015'!$A:$A,0),MATCH(D$6,'BS 2015'!$1:$1,0)) -> 28.7 | E15: =INDEX('BS 2016'!$1:$1048576,MATCH(BS!$B15,'BS 2016'!$A:$A,0),MATCH(E$6,'BS 2016'!$1:$1,0)) -> 28.7 | F15: =$E$15 -> 28.7 | G15: =$E$15 -> 28.7 | H15: =$E$15 -> 28.7 | I15: =$E$15 -> 28.7 | J15: =$E$15 -> 28.7
B16: Financial Liabilities | C16: =INDEX('BS 2014'!$1:$1048576,MATCH(BS!$B16,'BS 2014'!$A:$A,0),MATCH(C$6,'BS 2014'!$1:$1,0)) -> 615.8 | D16: =INDEX('BS 2015'!$1:$1048576,MATCH(BS!$B16,'BS 2015'!$A:$A,0),MATCH(D$6,'BS 2015'!$1:$1,0)) -> 610.4 | E16: =INDEX('BS 2016'!$1:$1048576,MATCH(BS!$B16,'BS 2016'!$A:$A,0),MATCH(E$6,'BS 2016'!$1:$1,0)) -> 605 | F16: ='Financial Liabilities'!F10 -> 565.17885 | G16: ='Financial Liabilities'!G10 -> 521.77379 | H16: ='Financial Liabilities'!H10 -> 474.46227 | I16: ='Financial Liabilities'!I10 -> 422.89272 | J16: ='Financial Liabilities'!J10 -> 366.68191
B17: Other liabilities | C17: =INDEX('BS 2014'!$1:$1048576,MATCH(BS!$B17,'BS 2014'!$A:$A,0),MATCH(C$6,'BS 2014'!$1:$1,0)) -> 48.3 | D17: =INDEX('BS 2015'!$1:$1048576,MATCH(BS!$B17,'BS 2015'!$A:$A,0),MATCH(D$6,'BS 2015'!$1:$1,0)) -> 43.3 | E17: =INDEX('BS 2016'!$1:$1048576,MATCH(BS!$B17,'BS 2016'!$A:$A,0),MATCH(E$6,'BS 2016'!$1:$1,0)) -> 38.9 | F17: =F25*'P&L'!H4 -> 45.753669 | G17: =G25*'P&L'!I4 -> 47.126279 | H17: =H25*'P&L'!J4 -> 48.540068 | I17: =I25*'P&L'!K4 -> 49.99627 | J17: =J25*'P&L'!L4 -> 51.496158
B18: Equity | C18: =INDEX('BS 2014'!$1:$1048576,MATCH(BS!$B18,'BS 2014'!$A:$A,0),MATCH(C$6,'BS 2014'!$1:$1,0)) -> 167.5 | D18: =INDEX('BS 2015'!$1:$1048576,MATCH(BS!$B18,'BS 2015'!$A:$A,0),MATCH(D$6,'BS 2015'!$1:$1,0)) -> 196.7 | E18: =INDEX('BS 2016'!$1:$1048576,MATCH(BS!$B18,'BS 2016'!$A:$A,0),MATCH(E$6,'BS 2016'!$1:$1,0)) -> 485.3 | F18: ='Equity Schedule'!F11 -> 691.01555 | G18: ='Equity Schedule'!G11 -> 905.08696 | H18: ='Equity Schedule'!H11 -> 1127.8519 | I18: ='Equity Schedule'!I11 -> 1359.666 | J18: ='Equity Schedule'!J11 -> 1600.9036
B19: Liabilities & Equity | C19: =SUM(C14:C18) -> 932.1 | D19: =SUM(D14:D18) -> 948 | E19: =SUM(E14:E18) -> 1226.8 | F19: =SUM(F14:F18) -> 1400.5169 | G19: =SUM(G14:G18) -> 1574.6519 | H19: =SUM(H14:H18) -> 1753.6781 | I19: =SUM(I14:I18) -> 1937.6025 | J19: =SUM(J14:J18) -> 2126.4196
B21: DSO | C21: =(C7/'P&L'!B4)*360 -> 17.728953 | D21: =(D7/'P&L'!C4)*360 -> 18.675603 | E21: =(E7/'P&L'!D4)*360 -> 20.048684 | F21: =AVERAGE($C21:$E21) -> 18.817747 | G21: =AVERAGE($C21:$E21) -> 18.817747 | H21: =AVERAGE($C21:$E21) -> 18.817747 | I21: =AVERAGE($C21:$E21) -> 18.817747 | J21: =AVERAGE($C21:$E21) -> 18.817747
B22: DPO | C22: =-1*(C14/'P&L'!B$5)*360 -> 17.473233 | D22: =-1*(D14/'P&L'!C$5)*360 -> 17.934924 | E22: =-1*(E14/'P&L'!D$5)*360 -> 18.144843 | F22: =AVERAGE($C22:$E22) -> 17.851 | G22: =AVERAGE($C22:$E22) -> 17.851 | H22: =AVERAGE($C22:$E22) -> 17.851 | I22: =AVERAGE($C22:$E22) -> 17.851 | J22: =AVERAGE($C22:$E22) -> 17.851
B23: DIO | C23: =-1*(C8/'P&L'!B$5)*360 -> 21.841542 | D23: =-1*(D8/'P&L'!C$5)*360 -> 23.947939 | E23: =-1*(E8/'P&L'!D$5)*360 -> 28.968544 | F23: =AVERAGE($C23:$E23) -> 24.919342 | G23: =AVERAGE($C23:$E23) -> 24.919342 | H23: =AVERAGE($C23:$E23) -> 24.919342 | I23: =AVERAGE($C23:$E23) -> 24.919342 | J23: =AVERAGE($C23:$E23) -> 24.919342
B24: Other Assets % | C24: =(C11/'P&L'!B$4) -> 0.015708419 | D24: =(D11/'P&L'!C$4) -> 0.015717158 | E24: =(E11/'P&L'!D$4) -> 0.022368421 | F24: =AVERAGE($C24:$E24) -> 0.017931333 | G24: =AVERAGE($C24:$E24) -> 0.017931333 | H24: =AVERAGE($C24:$E24) -> 0.017931333 | I24: =AVERAGE($C24:$E24) -> 0.017931333 | J24: =AVERAGE($C24:$E24) -> 0.017931333
B25: Other Liabilities % | C25: =C17/'P&L'!B$4 -> 0.016529774 | D25: =D17/'P&L'!C$4 -> 0.014510724 | E25: =E17/'P&L'!D$4 -> 0.012796053 | F25: =AVERAGE($C25:$E25) -> 0.014612184 | G25: =AVERAGE($C25:$E25) -> 0.014612184 | H25: =AVERAGE($C25:$E25) -> 0.014612184 | I25: =AVERAGE($C25:$E25) -> 0.014612184 | J25: =AVERAGE($C25:$E25) -> 0.014612184
B29: Check = | C29: =C19-C12 -> 0 | D29: =D19-D12 -> 0 | E29: =E19-E12 -> 0 | F29: =F19-F12 -> 0 | G29: =G19-G12 -> 0 | H29: =H19-H12 -> 0 | I29: =I19-I12 -> 0 | J29: =J19-J12 -> 0

Sheet FA Roll Forward
B2: Fixed Asset Rolll Forward
F4: Forecast
B6: $ in million | C6: 42004 | D6: 42369 | E6: 42735 | F6: 43100 | G6: 43465 | H6: 43830 | I6: 44196 | J6: 44561
B7: Beginning PP&E | D7: 632.5 | E7: =D10 -> 632.5 | F7: =E10 -> 659.5 | G7: =F10 -> 673.57628 | H7: =G10 -> 687.95301 | I7: =H10 -> 702.63659 | J7: =I10 -> 717.63358
B8: D&A | D8: ='P&L'!C9 -> -44 | E8: ='P&L'!D9 -> -41 | F8: =-F$7*F12 -> -44.314229 | G8: =-G$7*G12 -> -45.260067 | H8: =-H$7*H12 -> -46.226092 | I8: =-I$7*I12 -> -47.212736 | J8: =-J$7*J12 -> -48.220438
B9: Capex | D9: =D10-D8-D7 -> 44 | E9: =E10-E8-E7 -> 68 | F9: =F$7*F13 -> 58.390514 | G9: =G$7*G13 -> 59.636794 | H9: =H$7*H13 -> 60.909674 | I9: =I$7*I13 -> 62.209722 | J9: =J$7*J13 -> 63.537519
B10: Ending PP&E | C10: =SUM(C7:C9) -> 0 | D10: 632.5 | E10: =BS!E9 -> 659.5 | F10: =SUM(F7:F9) -> 673.57628 | G10: =SUM(G7:G9) -> 687.95301 | H10: =SUM(H7:H9) -> 702.63659 | I10: =SUM(I7:I9) -> 717.63358 | J10: =SUM(J7:J9) -> 732.95066
B12: D&A as a beginnign value of PP&E | D12: =-D8/D7 -> 0.069565217 | E12: =-E8/E7 -> 0.064822134 | F12: =AVERAGE($D12:$E12) -> 0.067193676 | G12: =AVERAGE($D12:$E12) -> 0.067193676 | H12: =AVERAGE($D12:$E12) -> 0.067193676 | I12: =AVERAGE($D12:$E12) -> 0.067193676 | J12: =AVERAGE($D12:$E12) -> 0.067193676
B13: Capex as a beginning of PP&E | D13: =D9/D7 -> 0.069565217 | E13: =E9/E7 -> 0.10750988 | F13: =AVERAGE($D13:$E13) -> 0.088537549 | G13: =AVERAGE($D13:$E13) -> 0.088537549 | H13: =AVERAGE($D13:$E13) -> 0.088537549 | I13: =AVERAGE($D13:$E13) -> 0.088537549 | J13: =AVERAGE($D13:$E13) -> 0.088537549

Sheet Financial Liabilities
B2: Financial Liabilities
F4: Forecast
B6: $ in million | C6: 42004 | D6: 42369 | E6: 42735 | F6: 43100 | G6: 43465 | H6: 43830 | I6: 44196 | J6: 44561
B7: Beginning Debt | D7: =C10 -> 615.8 | E7: =D10 -> 610.4 | F7: =E10 -> 605 | G7: =F10 -> 565.17885 | H7: =G10 -> 521.77379 | I7: =H10 -> 474.46227 | J7: =I10 -> 422.89272
B8: New Debt | D8: 0 | E8: 0 | F8: 0 | G8: 0 | H8: 0 | I8: 0 | J8: 0
B9: Principal Repayment | D9: =D10-D7 -> -5.4 | E9: =E10-E7 -> -5.4 | F9: =C19 -> -39.821154 | G9: =D19 -> -43.405058 | H9: =E19 -> -47.311514 | I9: =F19 -> -51.56955 | J9: =G19 -> -56.210809
B10: Ending Debt | C10: =BS!C16 -> 615.8 | D10: =BS!D16 -> 610.4 | E10: =BS!E16 -> 605 | F10: =SUM(F7:F9) -> 565.17885 | G10: =SUM(G7:G9) -> 521.77379 | H10: =SUM(H7:H9) -> 474.46227 | I10: =SUM(I7:I9) -> 422.89272 | J10: =SUM(J7:J9) -> 366.68191
B12: Debt to be repaid (in years) | C12: 10
B13: Interest rate | C13: 0.09
B14: Annual payment | C14: =PMT(C13,C12,E10) -> -94.271154
B16: Period | C16: 1 | D16: 2 | E16: 3 | F16: 4 | G16: 5 | H16: 6 | I16: 7 | J16: 8 | K16: 9 | L16: 10
B17: Payment | C17: =$C$14 -> -94.271154 | D17: =$C$14 -> -94.271154 | E17: =$C$14 -> -94.271154 | F17: =$C$14 -> -94.271154 | G17: =$C$14 -> -94.271154 | H17: =$C$14 -> -94.271154 | I17: =$C$14 -> -94.271154 | J17: =$C$14 -> -94.271154 | ... L17: =$C$14 -> -94.271154
B18: Interest expense | C18: =-C13*E10 -> -54.45 | D18: =-C20*$C$13 -> -50.866096 | E18: =-D20*$C$13 -> -46.959641 | F18: =-E20*$C$13 -> -42.701605 | G18: =-F20*$C$13 -> -38.060345 | H18: =-G20*$C$13 -> -33.001372 | I18: =-H20*$C$13 -> -27.487092 | J18: =-I20*$C$13 -> -21.476526 | K18: =-J20*$C$13 -> -14.92501 | L18: =-K20*$C$13 -> -7.7838568
B19: Debt repayment | C19: =C17-C18 -> -39.821154 | D19: =D17-D18 -> -43.405058 | E19: =E17-E18 -> -47.311514 | F19: =F17-F18 -> -51.56955 | G19: =G17-G18 -> -56.210809 | H19: =H17-H18 -> -61.269782 | I19: =I17-I18 -> -66.784062 | J19: =J17-J18 -> -72.794628 | ... L19: =L17-L18 -> -86.487298
B20: Residual debt | C20: =E10+C19 -> 565.17885 | D20: =C20+D19 -> 521.77379 | E20: =D20+E19 -> 474.46227 | F20: =E20+F19 -> 422.89272 | G20: =F20+G19 -> 366.68191 | H20: =G20+H19 -> 305.41213 | I20: =H20+I19 -> 238.62807 | J20: =I20+J19 -> 165.83344 | K20: =J20+K19 -> 86.487298 | L20: =K20+L19 -> 2.2737368e-13

Sheet Equity Schedule
B2: Equity Schedule
F4: Forecast
B6: $ in million | C6: 42004 | D6: 42369 | E6: 42735 | F6: 43100 | G6: 43465 | H6: 43830 | I6: 44196 | J6: 44561
B7: Beginning equity | F7: =E11 -> 485.3 | G7: =F11 -> 691.01555 | H7: =G11 -> 905.08696 | I7: =H11 -> 1127.8519 | J7: =I11 -> 1359.666
B8: Increasing of capital | F8: 0 | G8: 0 | H8: 0 | I8: 0 | J8: 0
B9: Net income (loss) | F9: ='P&L'!H14 -> 342.85925 | G9: ='P&L'!I14 -> 356.78567 | H9: ='P&L'!J14 -> 371.27498 | I9: ='P&L'!K14 -> 386.35676 | J9: ='P&L'!L14 -> 402.0626
B10: Dividends | F10: =IF(F9>0,-F13*F9) -> -137.1437 | G10: =IF(G9>0,-G13*G9) -> -142.71427 | H10: =IF(H9>0,-H13*H9) -> -148.50999 | I10: =IF(I9>0,-I13*I9) -> -154.5427 | J10: =IF(J9>0,-J13*J9) -> -160.82504
B11: Ending equity | C11: =SUM(C7:C10) -> 0 | D11: =SUM(D7:D10) -> 0 | E11: =BS!E18 -> 485.3 | F11: =SUM(F7:F10) -> 691.01555 | G11: =SUM(G7:G10) -> 905.08696 | H11: =SUM(H7:H10) -> 1127.8519 | I11: =SUM(I7:I10) -> 1359.666 | J11: =SUM(J7:J10) -> 1600.9036
B13: Dividends as a % of Net Income | F13: 0.4 | G13: 0.4 | H13: 0.4 | I13: 0.4 | J13: 0.4
B14: Capex as a beginning of PP&E | D14: =D10/D7 -> #DIV/0! | E14: =E10/E7 -> #DIV/0! | F14: =AVERAGE($D14:$E14) -> #DIV/0! | G14: =AVERAGE($D14:$E14) -> #DIV/0! | H14: =AVERAGE($D14:$E14) -> #DIV/0! | I14: =AVERAGE($D14:$E14) -> #DIV/0! | J14: =AVERAGE($D14:$E14) -> #DIV/0!

Sheet Cash flow
B2: Cash Flow
C3: Forecasting
B4: $ in million | C4: 2017 | D4: 2018 | E4: 2019 | F4: 2020 | G4: 2021
B5: EBITDA | C5: ='P&L'!H8 -> 626.24 | D5: ='P&L'!I8 -> 645.0272 | E5: ='P&L'!J8 -> 664.37802 | F5: ='P&L'!K8 -> 684.30936 | G5: ='P&L'!L8 -> 704.83864
B6: Interest expenses | C6: ='P&L'!H11 -> -54.45 | D6: ='P&L'!I11 -> -50.866096 | E6: ='P&L'!J11 -> -46.959641 | F6: ='P&L'!K11 -> -42.701605 | G6: ='P&L'!L11 -> -38.060345
B7: Taxes | C7: ='P&L'!H13 -> -184.61652 | D7: ='P&L'!I13 -> -192.11536 | E7: ='P&L'!J13 -> -199.9173 | F7: ='P&L'!K13 -> -208.03826 | G7: ='P&L'!L13 -> -216.49525
B8: Change in Trade receivables | C8: =-(BS!F7-BS!E7) -> 5.6274206 | D8: =-(BS!G7-BS!F7) -> -4.9101774 | E8: =-(BS!H7-BS!G7) -> -5.0574827 | F8: =-(BS!I7-BS!H7) -> -5.2092072 | G8: =-(BS!J7-BS!I7) -> -5.3654834
B9: Change in Inventory | C9: =-(BS!F8-BS!E8) -> 12.465696 | D9: =-(BS!G8-BS!F8) -> -2.9260291 | E9: =-(BS!H8-BS!G8) -> -3.01381 | F9: =-(BS!I8-BS!H8) -> -3.1042243 | G9: =-(BS!J8-BS!I8) -> -3.197351
B10: Change in Trade Payables | C10: =BS!F14-BS!E14 -> 0.96881427 | D10: =BS!G14-BS!F14 -> 2.0960644 | E10: =BS!H14-BS!G14 -> 2.1589464 | F10: =BS!I14-BS!H14 -> 2.2237148 | G10: =BS!J14-BS!I14 -> 2.2904262
B11: Change in Other Assests | C11: =-(BS!F11-BS!E11) -> 11.853411 | D11: =-(BS!G11-BS!F11) -> -1.6843977 | E11: =-(BS!H11-BS!G11) -> -1.7349296 | F11: =-(BS!I11-BS!H11) -> -1.7869775 | G11: =-(BS!J11-BS!I11) -> -1.8405868
B12: Change in Other Liabilities | C12: =BS!F17-BS!E17 -> 6.8536691 | D12: =BS!G17-BS!F17 -> 1.3726101 | E12: =BS!H17-BS!G17 -> 1.4137884 | F12: =BS!I17-BS!H17 -> 1.456202 | G12: =BS!J17-BS!I17 -> 1.4998881
B13: Capex | C13: =-'FA Roll Forward'!F9 -> -58.390514 | D13: =-'FA Roll Forward'!G9 -> -59.636794 | E13: =-'FA Roll Forward'!H9 -> -60.909674 | F13: =-'FA Roll Forward'!I9 -> -62.209722 | G13: =-'FA Roll Forward'!J9 -> -63.537519
B14: Operating Cash flow | C14: =SUM(C5:C13) -> 366.55198 | D14: =SUM(D5:D13) -> 336.35702 | E14: =SUM(E5:E13) -> 350.35791 | F14: =SUM(F5:F13) -> 364.93928 | G14: =SUM(G5:G13) -> 380.13242
B15: Dividends | C15: ='Equity Schedule'!F10 -> -137.1437 | D15: ='Equity Schedule'!G10 -> -142.71427 | E15: ='Equity Schedule'!H10 -> -148.50999 | F15: ='Equity Schedule'!I10 -> -154.5427 | G15: ='Equity Schedule'!J10 -> -160.82504
B16: Change in Financial liabilities | C16: ='Financial Liabilities'!F10-'Financial Liabilities'!E10 -> -39.821154 | D16: ='Financial Liabilities'!G10-'Financial Liabilities'!F10 -> -43.405058 | E16: ='Financial Liabilities'!H10-'Financial Liabilities'!G10 -> -47.311514 | F16: ='Financial Liabilities'!I10-'Financial Liabilities'!H10 -> -51.56955 | G16: ='Financial Liabilities'!J10-'Financial Liabilities'!I10 -> -56.210809
B17: Change in Provisions | C17: =BS!F15-BS!E15 -> 0 | D17: =BS!G15-BS!F15 -> 0 | E17: =BS!H15-BS!G15 -> 0 | F17: =BS!I15-BS!H15 -> 0 | G17: =BS!J15-BS!I15 -> 0
B18: Change in equity | C18: ='Equity Schedule'!F11-'Equity Schedule'!E11-'Equity Schedule'!F9-'Equity Schedule'!F10 -> 0 | D18: ='Equity Schedule'!G11-'Equity Schedule'!F11-'Equity Schedule'!G9-'Equity Schedule'!G10 -> 0 | E18: ='Equity Schedule'!H11-'Equity Schedule'!G11-'Equity Schedule'!H9-'Equity Schedule'!H10 -> 0 | F18: ='Equity Schedule'!I11-'Equity Schedule'!H11-'Equity Schedule'!I9-'Equity Schedule'!I10 -> 0 | G18: ='Equity Schedule'!J11-'Equity Schedule'!I11-'Equity Schedule'!J9-'Equity Schedule'!J10 -> 0
B19: Net Cash Flow | C19: =SUM(C14:C18) -> 189.58712 | D19: =SUM(D14:D18) -> 150.23769 | E19: =SUM(E14:E18) -> 154.53641 | F19: =SUM(F14:F18) -> 158.82703 | G19: =SUM(G14:G18) -> 163.09657
